package tech.luckyblock.mcmod.ctnhenergy.registry;

import appeng.core.definitions.AEBlocks;
import com.glodblock.github.extendedae.common.EPPItemAndBlock;
import com.gregtechceu.gtceu.GTCEu;
import com.gregtechceu.gtceu.api.data.RotationState;
import com.gregtechceu.gtceu.api.machine.MultiblockMachineDefinition;
import com.gregtechceu.gtceu.api.machine.multiblock.PartAbility;
import com.gregtechceu.gtceu.api.machine.property.GTMachineModelProperties;
import com.gregtechceu.gtceu.api.machine.trait.RecipeLogic;
import com.gregtechceu.gtceu.api.pattern.FactoryBlockPattern;
import com.gregtechceu.gtceu.api.pattern.Predicates;
import net.minecraftforge.client.model.generators.BlockModelBuilder;
import net.minecraftforge.client.model.generators.ConfiguredModel;
import tech.luckyblock.mcmod.ctnhenergy.CTNHEnergy;
import tech.luckyblock.mcmod.ctnhenergy.api.CEPredicates;
import tech.luckyblock.mcmod.ctnhenergy.common.quantumcomputer.machine.QuantumComputerMultiblockMachine;

import static com.gregtechceu.gtceu.api.pattern.Predicates.abilities;
import static com.gregtechceu.gtceu.common.data.GTBlocks.ADVANCED_COMPUTER_CASING;
import static com.gregtechceu.gtceu.common.data.GTBlocks.COMPUTER_CASING;
import static tech.luckyblock.mcmod.ctnhenergy.CTNHEnergy.REGISTRATE;

@SuppressWarnings("removal")
public class CEMultiblock {

    static {
        REGISTRATE.creativeModeTab(() -> CECreativeModeTabs.ITEM);
    }

    public static MultiblockMachineDefinition JIUZHANG_QUANTUM_COMPUTER;

    public static void init() {
        JIUZHANG_QUANTUM_COMPUTER = REGISTRATE.multiblock(
                        "jiuzhang_quantum_computer",
                        QuantumComputerMultiblockMachine::new
                )
                .cnLangValue("§6九章§r | §d量子超算§r")
                .langValue("§6JIUZHANG§r | §dQuantum Supercomputing§r")
                .rotationState(RotationState.NON_Y_AXIS)
                .recipeType(CERecipeTypes.QUANTUM_COMPUTER)
                .appearanceBlock(CEBlocks.LIGHT_COMPUTER_CASING)
                .pattern(definition -> FactoryBlockPattern.start()
                        .aisle("AAAAAAA###AAAAAAA", "AAAAAAA###AAAAAAA", "AAAAAAA###AAAAAAA", "AAAAAAA###AAAAAAA", "AAAAAAA###AAAAAAA", "AAAAAAA###AAAAAAA", "AAAAAAA###AAAAAAA", "#################", "#################", "#################", "AAAAAAA###AAAAAAA", "AAAAAAA###AAAAAAA", "AAAAAAA###AAAAAAA", "AAAAAAA###AAAAAAA", "AAAAAAA###AAAAAAA", "AAAAAAA###AAAAAAA", "AAAAAAA###AAAAAAA")
                        .aisle("AAAAAAA###AAAAAAA", "ABBBBBC###CBBBBBA", "ABBBBBC###CBBBBBA", "ABBBBBC###CBBBBBA", "ABBBBBC###CBBBBBA", "ABBBBBC###CBBBBBA", "ACCCCCC###CCCCCCA", "#################", "#################", "#################", "ACCCCCC###CCCCCCA", "ABBBBBC###CBBBBBA", "ABBBBBC###CBBBBBA", "ABBBBBC###CBBBBBA", "ABBBBBC###CBBBBBA", "ABBBBBC###CBBBBBA", "AAAAAAA###AAAAAAA")
                        .aisle("AAAAAAA###AAAAAAA", "ABBBBBC###CBBBBBA", "ABBBBBD###DBBBBBA", "ABBBBBD###DBBBBBA", "ABBBBBD###DBBBBBA", "ABBBBBD###DBBBBBA", "ACDDDDDEEEDDDDDCA", "######EFFFE######", "######EFGFE######", "######EFFFE######", "ACDDDDDEEEDDDDDCA", "ABBBBBD###DBBBBBA", "ABBBBBD###DBBBBBA", "ABBBBBD###DBBBBBA", "ABBBBBD###DBBBBBA", "ABBBBBC###CBBBBBA", "AAAAAAA###AAAAAAA")
                        .aisle("AAAAAAA###AAAAAAA", "ABBBBBC###CBBBBBA", "ABBBBBD###DBBBBBA", "ABBBBBC###CBBBBBA", "ABBBBCCEFECCBBBBA", "ABBBCCEEFEECCBBBA", "ACDCCEEHHHEECCDCA", "####EEHHHHHEE####", "####FFHHHHHFF####", "####EEHHHHHEE####", "ACDCCEEHHHEECCDCA", "ABBBCCEEFEECCBBBA", "ABBBBCCEFECCBBBBA", "ABBBBBC###CBBBBBA", "ABBBBBD###DBBBBBA", "ABBBBBC###CBBBBBA", "AAAAAAA###AAAAAAA")
                        .aisle("AAAAAAA###AAAAAAA", "ABBBBBC###CBBBBBA", "ABBBBBD###DBBBBBA", "ABBBBCCEFECCBBBBA", "ABBBCEEHHHEECBBBA", "ABBCEEHHHHHEECBBA", "ACDCEHHHHHHHECDCA", "###EHHHHHHHHHE###", "###FHHHHHHHHHF###", "###EHHHHHHHHHE###", "ACDCEHHHHHHHECDCA", "ABBCEEHHHHHEECBBA", "ABBBCEEHHHEECBBBA", "ABBBBCCEFECCBBBBA", "ABBBBBD###DBBBBBA", "ABBBBBC###CBBBBBA", "AAAAAAA###AAAAAAA")
                        .aisle("AAAAAAA###AAAAAAA", "ABBBBBC###CBBBBBA", "ABBBBBD###DBBBBBA", "ABBBCCEEFEECCBBBA", "ABBCEEHHHHHEECBBA", "ABBCEHHHHHHHECBBA", "ACDEHHHHHHHHHEDCA", "###EHHHHHHHHHE###", "###FHHHHHHHHHF###", "###EHHHHHHHHHE###", "ACDEHHHHHHHHHEDCA", "ABBCEHHHHHHHECBBA", "ABBCEEHHHHHEECBBA", "ABBBCCEEFEECCBBBA", "ABBBBBD###DBBBBBA", "ABBBBBC###CBBBBBA", "AAAAAAA###AAAAAAA")
                        .aisle("AAAAAAA###AAAAAAA", "ACCCCCC###CCCCCCA", "ACDDDDDEEEDDDDDCA", "ACDCCEEHHHEECCDCA", "ACDCEHHHHHHHECDCA", "ACDEHHHHHHHHHEDCA", "ACDEHHHHHHHHHEDCA", "##EHHHHHHHHHHHE##", "##EHHHHHHHHHHHE##", "##EHHHHHHHHHHHE##", "ACDEHHHHHHHHHEDCA", "ACDEHHHHHHHHHEDCA", "ACDCEHHHHHHHECDCA", "ACDCCEEHHHEECCDCA", "ACDDDDDEEEDDDDDCA", "ACCCCCC###CCCCCCA", "AAAAAAA###AAAAAAA")
                        .aisle("#################", "#################", "######EFFFE######", "####EEHHHHHEE####", "###EHHHHHHHHHE###", "###EHHHHHHHHHE###", "##EHHHHHHHHHHHE##", "##FHHHHHHHHHHHF##", "##FHHHHHHHHHHHF##", "##FHHHHHHHHHHHF##", "##EHHHHHHHHHHHE##", "###EHHHHHHHHHE###", "###EHHHHHHHHHE###", "####EEHHHHHEE####", "######EFFFE######", "#################", "#################")
                        .aisle("#################", "#################", "######EFGFE######", "####FFHHHHHFF####", "###FHHHHHHHHHF###", "###FHHHHHHHHHF###", "##EHHHHHHHHHHHE##", "##FHHHHHHHHHHHF##", "##GHHHHHHHHHHHG##", "##FHHHHHHHHHHHF##", "##EHHHHHHHHHHHE##", "###FHHHHHHHHHF###", "###FHHHHHHHHHF###", "####FFHHHHHFF####", "######EFIFE######", "#################", "#################")
                        .aisle("#################", "#################", "######EFFFE######", "####EEHHHHHEE####", "###EHHHHHHHHHE###", "###EHHHHHHHHHE###", "##EHHHHHHHHHHHE##", "##FHHHHHHHHHHHF##", "##FHHHHHHHHHHHF##", "##FHHHHHHHHHHHF##", "##EHHHHHHHHHHHE##", "###EHHHHHHHHHE###", "###EHHHHHHHHHE###", "####EEHHHHHEE####", "######EFFFE######", "#################", "#################")
                        .aisle("AAAAAAA###AAAAAAA", "ACCCCCC###CCCCCCA", "ACDDDDDEEEDDDDDCA", "ACDCCEEHHHEECCDCA", "ACDCEHHHHHHHECDCA", "ACDEHHHHHHHHHEDCA", "ACDEHHHHHHHHHEDCA", "##EHHHHHHHHHHHE##", "##EHHHHHHHHHHHE##", "##EHHHHHHHHHHHE##", "ACDEHHHHHHHHHEDCA", "ACDEHHHHHHHHHEDCA", "ACDCEHHHHHHHECDCA", "ACDCCEEHHHEECCDCA", "ACDDDDDEEEDDDDDCA", "ACCCCCC###CCCCCCA", "AAAAAAA###AAAAAAA")
                        .aisle("AAAAAAA###AAAAAAA", "ABBBBBC###CBBBBBA", "ABBBBBD###DBBBBBA", "ABBBCCEEFEECCBBBA", "ABBCEEHHHHHEECBBA", "ABBCEHHHHHHHECBBA", "ACDEHHHHHHHHHEDCA", "###EHHHHHHHHHE###", "###FHHHHHHHHHF###", "###EHHHHHHHHHE###", "ACDEHHHHHHHHHEDCA", "ABBCEHHHHHHHECBBA", "ABBCEEHHHHHEECBBA", "ABBBCCEEFEECCBBBA", "ABBBBBD###DBBBBBA", "ABBBBBC###CBBBBBA", "AAAAAAA###AAAAAAA")
                        .aisle("AAAAAAA###AAAAAAA", "ABBBBBC###CBBBBBA", "ABBBBBD###DBBBBBA", "ABBBBCCEFECCBBBBA", "ABBBCEEHHHEECBBBA", "ABBCEEHHHHHEECBBA", "ACDCEHHHHHHHECDCA", "###EHHHHHHHHHE###", "###FHHHHHHHHHF###", "###EHHHHHHHHHE###", "ACDCEHHHHHHHECDCA", "ABBCEEHHHHHEECBBA", "ABBBCEEHHHEECBBBA", "ABBBBCCEFECCBBBBA", "ABBBBBD###DBBBBBA", "ABBBBBC###CBBBBBA", "AAAAAAA###AAAAAAA")
                        .aisle("AAAAAAA###AAAAAAA", "ABBBBBC###CBBBBBA", "ABBBBBD###DBBBBBA", "ABBBBBC###CBBBBBA", "ABBBBCCEFECCBBBBA", "ABBBCCEEFEECCBBBA", "ACDCCEEHHHEECCDCA", "####EEHHHHHEE####", "####FFHHHHHFF####", "####EEHHHHHEE####", "ACDCCEEHHHEECCDCA", "ABBBCCEEFEECCBBBA", "ABBBBCCEFECCBBBBA", "ABBBBBC###CBBBBBA", "ABBBBBD###DBBBBBA", "ABBBBBC###CBBBBBA", "AAAAAAA###AAAAAAA")
                        .aisle("AAAAAAA###AAAAAAA", "ABBBBBC###CBBBBBA", "ABBBBBD###DBBBBBA", "ABBBBBD###DBBBBBA", "ABBBBBD###DBBBBBA", "ABBBBBD###DBBBBBA", "ACDDDDDEEEDDDDDCA", "######EFFFE######", "######EFJFE######", "######EFFFE######", "ACDDDDDEEEDDDDDCA", "ABBBBBD###DBBBBBA", "ABBBBBD###DBBBBBA", "ABBBBBD###DBBBBBA", "ABBBBBD###DBBBBBA", "ABBBBBC###CBBBBBA", "AAAAAAA###AAAAAAA")
                        .aisle("AAAAAAA###AAAAAAA", "ABBBBBC###CBBBBBA", "ABBBBBC###CBBBBBA", "ABBBBBC###CBBBBBA", "ABBBBBC###CBBBBBA", "ABBBBBC###CBBBBBA", "ACCCCCC###CCCCCCA", "#################", "#################", "#################", "ACCCCCC###CCCCCCA", "ABBBBBC###CBBBBBA", "ABBBBBC###CBBBBBA", "ABBBBBC###CBBBBBA", "ABBBBBC###CBBBBBA", "ABBBBBC###CBBBBBA", "AAAAAAA###AAAAAAA")
                        .aisle("AAAAAAA###AAAAAAA", "AAAAAAA###AAAAAAA", "AAAAAAA###AAAAAAA", "AAAAAAA###AAAAAAA", "AAAAAAA###AAAAAAA", "AAAAAAA###AAAAAAA", "AAAAAAA###AAAAAAA", "#################", "#################", "#################", "AAAAAAA###AAAAAAA", "AAAAAAA###AAAAAAA", "AAAAAAA###AAAAAAA", "AAAAAAA###AAAAAAA", "AAAAAAA###AAAAAAA", "AAAAAAA###AAAAAAA", "AAAAAAA###AAAAAAA")
                        .where("I", Predicates.blocks(CEBlocks.QUANTUM_COMPUTER_ME_NETWORK_PORT.get()))
                        .where("G", Predicates.blocks(AEBlocks.NOT_SO_MYSTERIOUS_CUBE.block())
                                .or(Predicates.abilities(PartAbility.COMPUTATION_DATA_RECEPTION).setExactLimit(1).setPreviewCount(1))
                        )
                        .where("D", Predicates.blocks(CEBlocks.ASSEMBLER_MATRIX_FRAME.get()))
                        .where("#", Predicates.any())
                        .where("C", Predicates.blocks(CEBlocks.ASSEMBLER_MATRIX_WALL.get()))
                        .where("E", Predicates.blocks(CEBlocks.QUANTUM_POINTING_BLOCK.get()))
                        .where("H", CEPredicates.craftingUnitBlock())
                        .where("J", Predicates.controller(Predicates.blocks(definition.get())))
                        .where("B", Predicates.air())
                        .where("A", Predicates.blocks(CEBlocks.QUANTUM_COMPUTER_CASING.get()))
                        .where("F", Predicates.blocks(CEBlocks.LIGHT_COMPUTER_CASING.get())
                                .or(Predicates.autoAbilities(CERecipeTypes.QUANTUM_COMPUTER))
                        )
                        .build())
                .workableCasingModel(CTNHEnergy.id("block/casings/light_computer_casing"),
                        CTNHEnergy.id("block/machine/quantum_computer"))
                .register();


    }
}
